Workbook

Sheet README
A1: Hillview Harmony: Business Analytics scenario model
A2: Quang, N. (2026) | MQBS3010 Capstone, Group 1I, Macquarie University | supports the Business Analytics chapter
A4: Author | B4: Quang, N. (Business Analytics), MQBS3010 Capstone Team Group 1I, Session 2, 2026.
A5: Purpose | B5: Scenario, sensitivity and simulation analysis behind the Business Analytics chapter. It re-runs the cost engine in Finance's FINAL workbooks (Drake, 2026a; 2026b; 2026c) under Low, Base and High demand, then tests how the Year 5 surplus compares with the 3% hurdle.
A6: How it ties to Finance | B6: The "Finance plan" scenario reproduces Finance's Year 5 operating surplus of $203,657 and headline ARR of 46.6% (Drake, 2026b, Calculations!H84 and H85) to within $1. Every figure quoted in the chapter is listed on the Chapter_Check sheet with a live link to the cell that produces it.
A7: Colour code | B7: Blue text = input copied from a source or an analyst assumption. Black = formula. Green = link to another sheet. Yellow fill = key analyst assumption to review.
A8: Sheets | B8: Summary (scenario results) > Inputs > Scenarios (live formulas, four blocks) > Returns (cash flows, lowest cash, payback) > Sensitivity and MonteCarlo (static output of analysis.py: Python, seed 42, 10,000 runs) > ModelRisk (live stress test) > Comparators (the three benchmark charities) > Recommendations (static output of tradeoff2.py) > Chapter_Check > References.
A9: Units | B9: Real 2026 dollars, ex GST. Year 1 is the set-up year with no school programs. A student-day is one student attending one program day.
A10: Key assumptions to review | B10: 1) Low, Base and High use overnight camp sizes of 50, 72 and 90 students (69%, 100% and 125% of Base); 90 is the most students Finance's plan allows. 2) Growth rates (4.8%, 6.2%, 8.5%) are the minimum, mean and maximum of four year-on-year revenue observations at three charities (Quang, 2026; Crusader Union, 2025; Stewart House, 2025; YMCA Camping Ltd, 2024, 2025); Crusader Union excludes capital-campaign donations. 3) Wet and dry hire stay at Finance's volumes in every scenario. 4) Cash flows after Year 5 are held flat at the Year 5 level and are used only to date payback. 5) The Year 3 restoration, conservation plan and 50% surplus reinvestment follow Finance's Section 2.5 layer (Drake, 2026b). 6) Hurdle: 3% of average investment ($13,100, Finance's basis); on the full $1 million endowment it is $30,000 (reported as a limit).
A11: Limitations | B11: Contractor cost scales with program days. Simulated inputs are independent and their ranges are our judgment, anchored to Finance's reliability ratings (Drake, 2026a). Growth comes from revenue, not student-days. Capacity (250 days x 270 students) is Finance's.
A12: How to cite | B12: In text: (Quang, 2026). Reference: Quang, N. (2026) Hillview Harmony: Business Analytics scenario model [Excel workbook]. MQBS3010 Group 1I, Macquarie University. Unpublished. Python code: Quang, N. (2026) Hillview Harmony: Business Analytics model [Python code]. MQBS3010 Group 1I, Macquarie University. Unpublished.
A13: Sources | B13: All sources are cited in Harvard style on the Inputs, Comparators, ModelRisk and Chapter_Check sheets and listed in full on the References sheet. Finance workbooks: (Drake, 2026a) cost structure and break-even; (Drake, 2026b) performance and returns; (Drake, 2026c) capital allocation.
A14: AI use (edit before submitting) | B14: Claude (Anthropic) was used to help rebuild Finance's cost engine in Python, run the scenarios, sensitivity and simulation, and build this workbook. The author set the questions, checked every input against Finance's workbooks and reconciled the outputs to the chapter. Delete or edit this line to match the unit's AI disclosure rules.

Sheet Summary
A1: Scenario summary
A2: All figures are formulas linked to Scenarios and Returns. Real 2026 dollars.
A4: Measure | B4: Low | C4: Base | D4: Finance plan | E4: High
A5: Launch volume multiplier (vs Finance Year 2) | B5: =Inputs!$C$42 | C5: =Inputs!$C$43 | D5: 1 | E5: =Inputs!$C$44
A6: Annual demand growth | B6: =Inputs!$D$36 | C6: =Inputs!$D$37 | D6: =(Inputs!G56/Inputs!D56)^(1/3)-1 | E6: =Inputs!$D$38
A7: Year 5 school student-days | B7: =Scenarios!G5 | C7: =Scenarios!G34 | D7: =Scenarios!G63 | E7: =Scenarios!G92
A8: Year 5 occupancy (% of capacity) | B8: =Scenarios!G6 | C8: =Scenarios!G35 | D8: =Scenarios!G64 | E8: =Scenarios!G93
A9: Year 5 revenue | B9: =Scenarios!G14 | C9: =Scenarios!G43 | D9: =Scenarios!G72 | E9: =Scenarios!G101
A10: Year 5 operating surplus (Finance 2.5 basis) | B10: =Scenarios!G30 | C10: =Scenarios!G59 | D10: =Scenarios!G88 | E10: =Scenarios!G117
A11: Year 5 total cost / revenue (incl. depreciation) | B11: =(Scenarios!G21+Scenarios!G23)/Scenarios!G14 | C11: =(Scenarios!G50+Scenarios!G52)/Scenarios!G43 | D11: =(Scenarios!G79+Scenarios!G81)/Scenarios!G72 | E11: =(Scenarios!G108+Scenarios!G110)/Scenarios!G101
A12: Average investment at Year 5 (2.2 base + reinvestment / 2) | B12: =Inputs!$B$14+(Inputs!$B$22+Inputs!$B$23+SUM(Scenarios!C28:G28))/2 | C12: =Inputs!$B$14+(Inputs!$B$22+Inputs!$B$23+SUM(Scenarios!C57:G57))/2 | D12: =Inputs!$B$14+(Inputs!$B$22+Inputs!$B$23+SUM(Scenarios!C86:G86))/2 | E12: =Inputs!$B$14+(Inputs!$B$22+Inputs!$B$23+SUM(Scenarios!C115:G115))/2
A13: Hurdle surplus: 3% of average investment | B13: =Inputs!$B$19*B12 | C13: =Inputs!$B$19*C12 | D13: =Inputs!$B$19*D12 | E13: =Inputs!$B$19*E12
A14: Hurdle surplus: 3% of $1M endowment | B14: =Inputs!$B$19*Inputs!$B$15 | C14: =Inputs!$B$19*Inputs!$B$15 | D14: =Inputs!$B$19*Inputs!$B$15 | E14: =Inputs!$B$19*Inputs!$B$15
A15: ARR, headline (Year 5 operating surplus / average investment) | B15: =Scenarios!G30/B12 | C15: =Scenarios!G59/C12 | D15: =Scenarios!G88/D12 | E15: =Scenarios!G117/E12
A16: ARR, conservative (Year 5 operating surplus / $1M) | B16: =Scenarios!G30/Inputs!$B$15 | C16: =Scenarios!G59/Inputs!$B$15 | D16: =Scenarios!G88/Inputs!$B$15 | E16: =Scenarios!G117/Inputs!$B$15
A17: ARR, 5-year average operating surplus / $1M (includes Year 1 loss) | B17: =AVERAGE(Scenarios!C30:G30)/Inputs!$B$15 | C17: =AVERAGE(Scenarios!C59:G59)/Inputs!$B$15 | D17: =AVERAGE(Scenarios!C88:G88)/Inputs!$B$15 | E17: =AVERAGE(Scenarios!C117:G117)/Inputs!$B$15
A18: Lowest year-end cash balance, Years 1-5 | B18: =Returns!C8 | C18: =Returns!C15 | D18: =Returns!C22 | E18: =Returns!C29
A19: Payback year (cash flows after Year 5 held flat at Year 5) | B19: =Returns!C9 | C19: =Returns!C16 | D19: =Returns!C23 | E19: =Returns!C30
A20: Meets 3% hurdle on headline ARR? | B20: =IF(Scenarios!G30>=B13,"Yes","No") | C20: =IF(Scenarios!G59>=C13,"Yes","No") | D20: =IF(Scenarios!G88>=D13,"Yes","No") | E20: =IF(Scenarios!G117>=E13,"Yes","No")
A21: Meets 3% hurdle on conservative ARR ($30k)? | B21: =IF(Scenarios!G30>=B14,"Yes","No") | C21: =IF(Scenarios!G59>=C14,"Yes","No") | D21: =IF(Scenarios!G88>=D14,"Yes","No") | E21: =IF(Scenarios!G117>=E14,"Yes","No")
A23: Reading the table: headline ARR (Finance's basis, Drake, 2026b) and conservative ARR on the $1 million endowment give different hurdles ($13,100 and $30,000). The chapter measures on the headline basis and reports the conservative basis as a limit.

Sheet Inputs
A1: Inputs (copied from Finance workbooks unless marked as analyst assumption)
A3: Scalar input | B3: Value | C3: Unit | D3: Source
A4: Day program price | B4: 98.602898 | C4: $ per student-day | D4: (Drake, 2026a) Pricing!C38 (cost-plus)
A5: Residential program price | B5: 172.14298 | C5: $ per student-night | D5: (Drake, 2026a) Pricing!C47
A6: Dry-hire rate | B6: 700 | C6: $ per room-day | D6: (Drake, 2026a) Assumptions!C8
A7: Wet-hire price | B7: 11306.667 | C7: $ per room-day | D7: (Drake, 2026a) Wet Hire Costs!C25
A8: Wet-hire bought-in services | B8: 9476 | C8: $ per room-day | D8: (Drake, 2026a) Wet Hire Costs!I17
A9: Contractor cost per program day (all activities) | B9: 3955 | C9: $ per program day | D9: (Drake, 2026a) Contractors!C20
A10: Catering | B10: 21.33 | C10: $ per student-night | D10: (Drake, 2026a) Cost Register!D6
A11: Workshop + market-garden supplies | B11: 6.65414 | C11: $ per school student-day | D11: (Drake, 2026a) Cost Register!D9 + D10
A12: Payment fees | B12: 0.02 | C12: % of revenue | D12: (Drake, 2026a) Cost Register!D15
A13: Nights per residential student-day | B13: =2/3 | C13: ratio | D13: (Drake, 2026a) 3-day, 2-night camp
A14: Average investment before reinvestment (2.2 ARR Base) | B14: 281956.57 | C14: $ | D14: (Drake, 2026c) ARR Base!B8
A15: Endowment | B15: 1000000 | C15: $ | D15: Capstone brief
A16: Capex (Year 0) | B16: 452583.19 | C16: $ | D16: (Drake, 2026c) Table 2.3!B18
A17: One-off set-up expenses (Year 0) | B17: 89500 | C17: $ | D17: (Drake, 2026c) Table 2.3!B33
A18: Day-to-day working capital | B18: 55664.972 | C18: $ | D18: (Drake, 2026c) Other Uses!B24
A19: Hurdle rate | B19: 0.03 | C19: % per year | D19: Capstone brief / Finance
A20: Working target rate | B20: 0.035 | C20: % per year | D20: (Drake, 2026a) Finance (CPI-aligned)
A21: Capacity (250 days x 270 students) | B21: 67500 | C21: student-days per year | D21: (Drake, 2026a) Assumptions!C26 x C27
A22: Wet-hire equipment, Year 3 (cash; depreciation already in 2.4) | B22: 35727 | C22: $ | D22: (Drake, 2026b) Inputs!C31
A23: Heritage restoration works, Year 3 | B23: 100000 | C23: $ | D23: (Drake, 2026b) Inputs!C32 (25-year life)
A24: Restoration useful life | B24: 25 | C24: years | D24: (Drake, 2026b) Inputs!E32
A25: Conservation management plan, Year 3 (expensed) | B25: 57500 | C25: $ | D25: (Drake, 2026b) Inputs!C33
... A28: Policy capex useful life | B28: 25 | C28: years | D28: (Drake, 2026b) Inputs!B49
A30: Benchmark growth observations (Quang, 2026; Crusader Union, 2025; Stewart House, 2025; YMCA Camping Ltd, 2024, 2025)
A31: Observation | B31: Prior-year revenue ($) | C31: Latest revenue ($) | D31: YoY growth
A32: Stewart House CY2023 to CY2024 | B32: 3162237 | C32: 3316064 | D32: =C32/B32-1
A33: Crusader Union FY23/24 to FY24/25 (excl. capital-campaign donations) | B33: 16813900 | C33: 18249398 | D33: =C33/B33-1
A34: YMCA Camping FY2023 to FY2024 | B34: 18921663 | C34: 19825707 | D34: =C34/B34-1
A35: YMCA Camping FY2024 to FY2025 | B35: 19825707 | C35: 21166872 | D35: =C35/B35-1
A36: Minimum (Low case) | D36: =MIN(D32:D35)
A37: Mean (Base case) | D37: =AVERAGE(D32:D35)
A38: Maximum (High case) | D38: =MAX(D32:D35)
A40: Launch-volume multipliers (overnight camp size: Low 50 is our assumption, Base 72 is Finance's Year 2 size, High 90 is Finance's maximum)
A41: Scenario | B41: Overnight students | C41: Multiplier vs Base
A42: Low | B42: 50 | C42: =B42/72
A43: Base | B43: 72 | C43: =B43/72
A44: High | B44: 90 | C44: =B44/72
A46: Finance plan by year
...

Sheet Scenarios
A1: Scenario engine (formulas; reproduces Finance cost logic)
A2: Low / Base / High: Year 2 volume = Finance Year 2 x launch multiplier, then grows at the benchmark rate. Finance plan: volumes copied from Finance.
A4: Low | B4: Unit | C4: Year 1 | D4: Year 2 | E4: Year 3 | F4: Year 4 | G4: Year 5
A5: School student-days | B5: student-days | C5: 0 | D5: =Inputs!D$56*Inputs!$C$42 | E5: =D5*(1+Inputs!$D$36) | F5: =E5*(1+Inputs!$D$36) | G5: =F5*(1+Inputs!$D$36)
A6: Occupancy (% of capacity) | B6: % | C6: =C5/Inputs!$B$21 | D6: =D5/Inputs!$B$21 | E6: =E5/Inputs!$B$21 | F6: =F5/Inputs!$B$21 | G6: =G5/Inputs!$B$21
A7: Day-program student-days | B7: student-days | C7: =C5*Inputs!C$57 | D7: =D5*Inputs!D$57 | E7: =E5*Inputs!E$57 | F7: =F5*Inputs!F$57 | G7: =G5*Inputs!G$57
A8: Residential student-days | B8: student-days | C8: =C5-C7 | D8: =D5-D7 | E8: =E5-E7 | F8: =F5-F7 | G8: =G5-G7
A9: Residential student-nights | B9: student-nights | C9: =C8*Inputs!$B$13 | D9: =D8*Inputs!$B$13 | E9: =E8*Inputs!$B$13 | F9: =F8*Inputs!$B$13 | G9: =G8*Inputs!$B$13
A10: Program days (cycles) | B10: days | C10: =IF(Inputs!C$58=0,0,C5/Inputs!C$58) | D10: =IF(Inputs!D$58=0,0,D5/Inputs!D$58) | E10: =IF(Inputs!E$58=0,0,E5/Inputs!E$58) | F10: =IF(Inputs!F$58=0,0,F5/Inputs!F$58) | G10: =IF(Inputs!G$58=0,0,G5/Inputs!G$58)
A11: School revenue | B11: $ | C11: =C7*Inputs!$B$4+C9*Inputs!$B$5 | D11: =D7*Inputs!$B$4+D9*Inputs!$B$5 | E11: =E7*Inputs!$B$4+E9*Inputs!$B$5 | F11: =F7*Inputs!$B$4+F9*Inputs!$B$5 | G11: =G7*Inputs!$B$4+G9*Inputs!$B$5
A12: Dry-hire revenue | B12: $ | C12: =Inputs!C$51*Inputs!$B$6 | D12: =Inputs!D$51*Inputs!$B$6 | E12: =Inputs!E$51*Inputs!$B$6 | F12: =Inputs!F$51*Inputs!$B$6 | G12: =Inputs!G$51*Inputs!$B$6
A13: Wet-hire revenue | B13: $ | C13: =Inputs!C$52*Inputs!$B$7 | D13: =Inputs!D$52*Inputs!$B$7 | E13: =Inputs!E$52*Inputs!$B$7 | F13: =Inputs!F$52*Inputs!$B$7 | G13: =Inputs!G$52*Inputs!$B$7
A14: Total revenue | B14: $ | C14: =C11+C12+C13 | D14: =D11+D12+D13 | E14: =E11+E12+E13 | F14: =F11+F12+F13 | G14: =G11+G12+G13
A15: Fixed cash costs (core staff + other fixed) | B15: $ | C15: =Inputs!C$53+Inputs!C$54 | D15: =Inputs!D$53+Inputs!D$54 | E15: =Inputs!E$53+Inputs!E$54 | F15: =Inputs!F$53+Inputs!F$54 | G15: =Inputs!G$53+Inputs!G$54
A16: Program contractors | B16: $ | C16: =C10*Inputs!$B$9 | D16: =D10*Inputs!$B$9 | E16: =E10*Inputs!$B$9 | F16: =F10*Inputs!$B$9 | G16: =G10*Inputs!$B$9
A17: Catering | B17: $ | C17: =C9*Inputs!$B$10 | D17: =D9*Inputs!$B$10 | E17: =E9*Inputs!$B$10 | F17: =F9*Inputs!$B$10 | G17: =G9*Inputs!$B$10
A18: Program supplies | B18: $ | C18: =C5*Inputs!$B$11 | D18: =D5*Inputs!$B$11 | E18: =E5*Inputs!$B$11 | F18: =F5*Inputs!$B$11 | G18: =G5*Inputs!$B$11
A19: Payment fees | B19: $ | C19: =C14*Inputs!$B$12 | D19: =D14*Inputs!$B$12 | E19: =E14*Inputs!$B$12 | F19: =F14*Inputs!$B$12 | G19: =G14*Inputs!$B$12
A20: Wet-hire event services | B20: $ | C20: =Inputs!C$52*Inputs!$B$8 | D20: =Inputs!D$52*Inputs!$B$8 | E20: =Inputs!E$52*Inputs!$B$8 | F20: =Inputs!F$52*Inputs!$B$8 | G20: =Inputs!G$52*Inputs!$B$8
A21: Total operating costs (cash) | B21: $ | C21: =C15+SUM(C16:C20) | D21: =D15+SUM(D16:D20) | E21: =E15+SUM(E16:E20) | F21: =F15+SUM(F16:F20) | G21: =G15+SUM(G16:G20)
A22: Operating surplus before depreciation | B22: $ | C22: =C14-C21 | D22: =D14-D21 | E22: =E14-E21 | F22: =F14-F21 | G22: =G14-G21
A23: Depreciation | B23: $ | C23: =Inputs!C$55 | D23: =Inputs!D$55 | E23: =Inputs!E$55 | F23: =Inputs!F$55 | G23: =Inputs!G$55
A24: Surplus after depreciation (2.4 basis, before reinvestment layer) | B24: $ | C24: =C22-C23 | D24: =D22-D23 | E24: =E22-E23 | F24: =F22-F23 | G24: =G22-G23
A25: Restoration depreciation (Year 3 onward) | B25: $ | C25: =IF(1>=3,Inputs!$B$23/Inputs!$B$24,0) | D25: =IF(2>=3,Inputs!$B$23/Inputs!$B$24,0) | E25: =IF(3>=3,Inputs!$B$23/Inputs!$B$24,0) | F25: =IF(4>=3,Inputs!$B$23/Inputs!$B$24,0) | G25: =IF(5>=3,Inputs!$B$23/Inputs!$B$24,0)
A26: Conservation management plan (Year 3, expensed) | B26: $ | C26: =IF(1=3,Inputs!$B$25,0) | D26: =IF(2=3,Inputs!$B$25,0) | E26: =IF(3=3,Inputs!$B$25,0) | F26: =IF(4=3,Inputs!$B$25,0) | G26: =IF(5=3,Inputs!$B$25,0)
A27: Surplus before reinvestment-policy capex | B27: $ | C27: =C24-C25-C26-0 | D27: =D24-D25-D26-C29 | E27: =E24-E25-E26-D29 | F27: =F24-F25-F26-E29 | G27: =G24-G25-G26-F29
A28: Policy capex (share of surplus, if positive) | B28: $ | C28: =IF(AND(1>=Inputs!$B$27,C27>0),Inputs!$B$26*C27,0) | D28: =IF(AND(2>=Inputs!$B$27,D27>0),Inputs!$B$26*D27,0) | E28: =IF(AND(3>=Inputs!$B$27,E27>0),Inputs!$B$26*E27,0) | F28: =IF(AND(4>=Inputs!$B$27,F27>0),Inputs!$B$26*F27,0) | G28: =IF(AND(5>=Inputs!$B$27,G27>0),Inputs!$B$26*G27,0)
A29: Cumulative policy depreciation | B29: $ | C29: =0+C28/Inputs!$B$28 | D29: =C29+D28/Inputs!$B$28 | E29: =D29+E28/Inputs!$B$28 | F29: =E29+F28/Inputs!$B$28 | G29: =F29+G28/Inputs!$B$28
A30: Operating surplus (Finance 2.5 basis) | B30: $ | C30: =C27-C28/Inputs!$B$28 | D30: =D27-D28/Inputs!$B$28 | E30: =E27-E28/Inputs!$B$28 | F30: =F27-F28/Inputs!$B$28 | G30: =G27-G28/Inputs!$B$28
A31: Reinvestment capex paid in cash | B31: $ | C31: =IF(1=3,Inputs!$B$22+Inputs!$B$23,0)+C28 | D31: =IF(2=3,Inputs!$B$22+Inputs!$B$23,0)+D28 | E31: =IF(3=3,Inputs!$B$22+Inputs!$B$23,0)+E28 | F31: =IF(4=3,Inputs!$B$22+Inputs!$B$23,0)+F28 | G31: =IF(5=3,Inputs!$B$22+Inputs!$B$23,0)+G28
A33: Base | B33: Unit | C33: Year 1 | D33: Year 2 | E33: Year 3 | F33: Year 4 | G33: Year 5
A34: School student-days | B34: student-days | C34: 0 | D34: =Inputs!D$56*Inputs!$C$43 | E34: =D34*(1+Inputs!$D$37) | F34: =E34*(1+Inputs!$D$37) | G34: =F34*(1+Inputs!$D$37)
A35: Occupancy (% of capacity) | B35: % | C35: =C34/Inputs!$B$21 | D35: =D34/Inputs!$B$21 | E35: =E34/Inputs!$B$21 | F35: =F34/Inputs!$B$21 | G35: =G34/Inputs!$B$21
A36: Day-program student-days | B36: student-days | C36: =C34*Inputs!C$57 | D36: =D34*Inputs!D$57 | E36: =E34*Inputs!E$57 | F36: =F34*Inputs!F$57 | G36: =G34*Inputs!G$57
A37: Residential student-days | B37: student-days | C37: =C34-C36 | D37: =D34-D36 | E37: =E34-E36 | F37: =F34-F36 | G37: =G34-G36
A38: Residential student-nights | B38: student-nights | C38: =C37*Inputs!$B$13 | D38: =D37*Inputs!$B$13 | E38: =E37*Inputs!$B$13 | F38: =F37*Inputs!$B$13 | G38: =G37*Inputs!$B$13
A39: Program days (cycles) | B39: days | C39: =IF(Inputs!C$58=0,0,C34/Inputs!C$58) | D39: =IF(Inputs!D$58=0,0,D34/Inputs!D$58) | E39: =IF(Inputs!E$58=0,0,E34/Inputs!E$58) | F39: =IF(Inputs!F$58=0,0,F34/Inputs!F$58) | G39: =IF(Inputs!G$58=0,0,G34/Inputs!G$58)
A40: School revenue | B40: $ | C40: =C36*Inputs!$B$4+C38*Inputs!$B$5 | D40: =D36*Inputs!$B$4+D38*Inputs!$B$5 | E40: =E36*Inputs!$B$4+E38*Inputs!$B$5 | F40: =F36*Inputs!$B$4+F38*Inputs!$B$5 | G40: =G36*Inputs!$B$4+G38*Inputs!$B$5
A41: Dry-hire revenue | B41: $ | C41: =Inputs!C$51*Inputs!$B$6 | D41: =Inputs!D$51*Inputs!$B$6 | E41: =Inputs!E$51*Inputs!$B$6 | F41: =Inputs!F$51*Inputs!$B$6 | G41: =Inputs!G$51*Inputs!$B$6
A42: Wet-hire revenue | B42: $ | C42: =Inputs!C$52*Inputs!$B$7 | D42: =Inputs!D$52*Inputs!$B$7 | E42: =Inputs!E$52*Inputs!$B$7 | F42: =Inputs!F$52*Inputs!$B$7 | G42: =Inputs!G$52*Inputs!$B$7
...

Sheet Returns
A1: Cash flows and return measures
A2: Year 0 = capex + set-up. Year 1 = set-up-year operating loss + working capital. Years 2-5 = cash surplus before depreciation, less the Year 3 conservation plan and reinvestment capex. Years 6-10 (used only to date payback) held flat at the Year 5 cash surplus, no further reinvestment. Working capital recovered in Year 10.
A4: Low | B4: Unit | C4: Year 0 | D4: Year 1 | E4: Year 2 | F4: Year 3 | G4: Year 4 | H4: Year 5 | I4: Year 6 | J4: Year 7 | K4: Year 8 | L4: Year 9 | M4: Year 10
A5: Cash flow | B5: $ | C5: =-(Inputs!$B$16+Inputs!$B$17) | D5: =Scenarios!C22-Inputs!$B$18-Scenarios!C26-Scenarios!C31 | E5: =Scenarios!D22-Scenarios!D26-Scenarios!D31 | F5: =Scenarios!E22-Scenarios!E26-Scenarios!E31 | G5: =Scenarios!F22-Scenarios!F26-Scenarios!F31 | H5: =Scenarios!G22-Scenarios!G26-Scenarios!G31 | I5: =Scenarios!G22 | J5: =Scenarios!G22 | K5: =Scenarios!G22 | L5: =Scenarios!G22 | M5: =Scenarios!G22+Inputs!$B$18
A6: Cumulative cash flow | B6: $ | C6: =C5 | D6: =C6+D5 | E6: =D6+E5 | F6: =E6+F5 | G6: =F6+G5 | H6: =G6+H5 | I6: =H6+I5 | J6: =I6+J5 | K6: =J6+K5 | ... M6: =L6+M5
A7: Year-end cash balance (endowment less launch spend, plus cash surplus less reinvestment) | B7: $ | C7: =Inputs!$B$15-(Inputs!$B$16+Inputs!$B$17) | D7: =C7+Scenarios!C22-Scenarios!C26-Scenarios!C31 | E7: =D7+Scenarios!D22-Scenarios!D26-Scenarios!D31 | F7: =E7+Scenarios!E22-Scenarios!E26-Scenarios!E31 | G7: =F7+Scenarios!F22-Scenarios!F26-Scenarios!F31 | H7: =G7+Scenarios!G22-Scenarios!G26-Scenarios!G31
A8: Lowest year-end cash balance, Years 1-5 | C8: =MIN(D7:H7)
A9: Payback year (first year cumulative cash >= 0) | C9: =IF(M6<0,"none within 10 yrs",COUNTIF(C6:M6,"<0"))
A11: Base | B11: Unit | C11: Year 0 | D11: Year 1 | E11: Year 2 | F11: Year 3 | G11: Year 4 | H11: Year 5 | I11: Year 6 | J11: Year 7 | K11: Year 8 | L11: Year 9 | M11: Year 10
A12: Cash flow | B12: $ | C12: =-(Inputs!$B$16+Inputs!$B$17) | D12: =Scenarios!C51-Inputs!$B$18-Scenarios!C55-Scenarios!C60 | E12: =Scenarios!D51-Scenarios!D55-Scenarios!D60 | F12: =Scenarios!E51-Scenarios!E55-Scenarios!E60 | G12: =Scenarios!F51-Scenarios!F55-Scenarios!F60 | H12: =Scenarios!G51-Scenarios!G55-Scenarios!G60 | I12: =Scenarios!G51 | J12: =Scenarios!G51 | K12: =Scenarios!G51 | L12: =Scenarios!G51 | M12: =Scenarios!G51+Inputs!$B$18
A13: Cumulative cash flow | B13: $ | C13: =C12 | D13: =C13+D12 | E13: =D13+E12 | F13: =E13+F12 | G13: =F13+G12 | H13: =G13+H12 | I13: =H13+I12 | J13: =I13+J12 | K13: =J13+K12 | ... M13: =L13+M12
A14: Year-end cash balance (endowment less launch spend, plus cash surplus less reinvestment) | B14: $ | C14: =Inputs!$B$15-(Inputs!$B$16+Inputs!$B$17) | D14: =C14+Scenarios!C51-Scenarios!C55-Scenarios!C60 | E14: =D14+Scenarios!D51-Scenarios!D55-Scenarios!D60 | F14: =E14+Scenarios!E51-Scenarios!E55-Scenarios!E60 | G14: =F14+Scenarios!F51-Scenarios!F55-Scenarios!F60 | H14: =G14+Scenarios!G51-Scenarios!G55-Scenarios!G60
A15: Lowest year-end cash balance, Years 1-5 | C15: =MIN(D14:H14)
A16: Payback year (first year cumulative cash >= 0) | C16: =IF(M13<0,"none within 10 yrs",COUNTIF(C13:M13,"<0"))
A18: Finance plan | B18: Unit | C18: Year 0 | D18: Year 1 | E18: Year 2 | F18: Year 3 | G18: Year 4 | H18: Year 5 | I18: Year 6 | J18: Year 7 | K18: Year 8 | L18: Year 9 | M18: Year 10
A19: Cash flow | B19: $ | C19: =-(Inputs!$B$16+Inputs!$B$17) | D19: =Scenarios!C80-Inputs!$B$18-Scenarios!C84-Scenarios!C89 | E19: =Scenarios!D80-Scenarios!D84-Scenarios!D89 | F19: =Scenarios!E80-Scenarios!E84-Scenarios!E89 | G19: =Scenarios!F80-Scenarios!F84-Scenarios!F89 | H19: =Scenarios!G80-Scenarios!G84-Scenarios!G89 | I19: =Scenarios!G80 | J19: =Scenarios!G80 | K19: =Scenarios!G80 | L19: =Scenarios!G80 | M19: =Scenarios!G80+Inputs!$B$18
A20: Cumulative cash flow | B20: $ | C20: =C19 | D20: =C20+D19 | E20: =D20+E19 | F20: =E20+F19 | G20: =F20+G19 | H20: =G20+H19 | I20: =H20+I19 | J20: =I20+J19 | K20: =J20+K19 | ... M20: =L20+M19
A21: Year-end cash balance (endowment less launch spend, plus cash surplus less reinvestment) | B21: $ | C21: =Inputs!$B$15-(Inputs!$B$16+Inputs!$B$17) | D21: =C21+Scenarios!C80-Scenarios!C84-Scenarios!C89 | E21: =D21+Scenarios!D80-Scenarios!D84-Scenarios!D89 | F21: =E21+Scenarios!E80-Scenarios!E84-Scenarios!E89 | G21: =F21+Scenarios!F80-Scenarios!F84-Scenarios!F89 | H21: =G21+Scenarios!G80-Scenarios!G84-Scenarios!G89
A22: Lowest year-end cash balance, Years 1-5 | C22: =MIN(D21:H21)
A23: Payback year (first year cumulative cash >= 0) | C23: =IF(M20<0,"none within 10 yrs",COUNTIF(C20:M20,"<0"))
A25: High | B25: Unit | C25: Year 0 | D25: Year 1 | E25: Year 2 | F25: Year 3 | G25: Year 4 | H25: Year 5 | I25: Year 6 | J25: Year 7 | K25: Year 8 | L25: Year 9 | M25: Year 10
A26: Cash flow | B26: $ | C26: =-(Inputs!$B$16+Inputs!$B$17) | D26: =Scenarios!C109-Inputs!$B$18-Scenarios!C113-Scenarios!C118 | E26: =Scenarios!D109-Scenarios!D113-Scenarios!D118 | F26: =Scenarios!E109-Scenarios!E113-Scenarios!E118 | G26: =Scenarios!F109-Scenarios!F113-Scenarios!F118 | H26: =Scenarios!G109-Scenarios!G113-Scenarios!G118 | I26: =Scenarios!G109 | J26: =Scenarios!G109 | K26: =Scenarios!G109 | L26: =Scenarios!G109 | M26: =Scenarios!G109+Inputs!$B$18
A27: Cumulative cash flow | B27: $ | C27: =C26 | D27: =C27+D26 | E27: =D27+E26 | F27: =E27+F26 | G27: =F27+G26 | H27: =G27+H26 | I27: =H27+I26 | J27: =I27+J26 | K27: =J27+K26 | ... M27: =L27+M26
A28: Year-end cash balance (endowment less launch spend, plus cash surplus less reinvestment) | B28: $ | C28: =Inputs!$B$15-(Inputs!$B$16+Inputs!$B$17) | D28: =C28+Scenarios!C109-Scenarios!C113-Scenarios!C118 | E28: =D28+Scenarios!D109-Scenarios!D113-Scenarios!D118 | F28: =E28+Scenarios!E109-Scenarios!E113-Scenarios!E118 | G28: =F28+Scenarios!F109-Scenarios!F113-Scenarios!F118 | H28: =G28+Scenarios!G109-Scenarios!G113-Scenarios!G118
A29: Lowest year-end cash balance, Years 1-5 | C29: =MIN(D28:H28)
A30: Payback year (first year cumulative cash >= 0) | C30: =IF(M27<0,"none within 10 yrs",COUNTIF(C27:M27,"<0"))

Sheet Sensitivity
A1: One-at-a-time sensitivity on the Finance plan (static output from analysis.py)
A2: Year 5 surplus after depreciation. Thresholds = multiplier of the plan value at which Year 5 surplus falls to the stated level. "Not reached" = the surplus stays above that level across the tested range.
A4: Variable | B4: Adverse multiplier | C4: Favourable multiplier | D4: Y5 surplus (adverse) | E4: Y5 surplus (favourable) | F4: Swing ($) | G4: Reliability (Finance) | H4: Multiplier at Y5 surplus = $0 | I4: Multiplier at 3% of avg. investment ($13.1k) | J4: Multiplier at 3% of $1M ($30k)
A5: School volume (all years) | B5: 0.8 | C5: 1.2 | D5: 57119.512 | E5: 347727.12 | F5: 290607.6 | G5: Medium | H5: 0.7234668 | I5: 0.74101616 | J5: 0.76366315
A6: Price per student | B6: 0.9 | C6: 1.1 | D6: 69384.481 | E6: 335779.1 | F6: 266394.62 | G6: Medium | H6: 0.84908396 | I6: 0.8586614 | J6: 0.87102084
A7: Contractor day rates | B7: 1.25 | C7: 0.75 | D7: 104001.9 | E7: 301814.98 | F7: 197813.09 | G7: Medium | H7: 1.5085839 | I7: 1.4763082 | J7: 1.4346571
A8: Core staff cost | B8: 1.2 | C8: 0.8 | D8: 143938.86 | E8: 262239.09 | F8: 118300.23 | G8: Low | H8: 1.6773778 | I8: 1.63439 | J8: 1.5789154
A9: Wet-hire volume | B9: 0 | C9: 1.5 | D9: 134029.34 | E9: 238470.98 | F9: 104441.64 | G9: Low | H9: Not reached | I9: Not reached | J9: Not reached
A10: Utilities allowance | B10: 1.5 | C10: 0.5 | D10: 165241.1 | E10: 241362.9 | F10: 76121.798 | G10: Low | H10: 3.6324845 | I10: 3.4654217 | J10: 3.2498314
A11: Catering cost per night | B11: 1.2 | C11: 0.8 | D11: 177859.13 | E11: 229110.53 | F11: 51251.404 | G11: Medium | H11: 2.5716905 | I11: 2.4719478 | J11: 2.3432325
A12: Heritage and grounds maintenance | B12: 3 | C12: 0.5 | D12: 165241.1 | E12: 213127.14 | F12: 47886.038 | G12: Low | H12: Not reached | I12: Not reached | J12: Not reached
A13: Marketing spend | B13: 1.3 | C13: 0.7 | D13: 184929.3 | E13: 222068.46 | F13: 37139.162 | G13: Medium | H13: Not reached | I13: Not reached | J13: 3.7690233
A15: Finance plan Year 5 surplus: $203,657. Volume threshold applies the multiplier to every year, including wet-hire-independent school volume; wet hire stays at plan. Schools-only accounting break-even (Finance FINAL): 10,486 student-days in Year 5, an 18.7% margin of safety.

Sheet MonteCarlo
A1: Monte Carlo (static output from analysis.py: 10,000 runs, seed 42, triangular distributions, inputs independent)
A3: Input | B3: Minimum | C3: Most likely | D3: Maximum | E3: Basis
A4: Launch volume multiplier (Year 2) | B4: 0.69444444 | C4: 1 | D4: 1.25 | E4: Low / Base / High overnight camp size: 50 / 72 / 90 students (90 = Finance maximum)
A5: Annual demand growth, case A (benchmark) | B5: 0.047778253 | C5: 0.062361674 | D5: 0.085375671 | E5: Min / mean / max of 4 comparable YoY observations
A6: Annual demand growth, case B (stress) | B6: 0 | C6: 0.062361674 | D6: 0.085375671 | E6: Floor set to 0% for survivorship bias (analyst judgement)
A7: Price multiplier | B7: 0.9 | C7: 1 | D7: 1.1 | E7: Medium reliability; cost-plus price, market ceiling untested
A8: Contractor day-rate multiplier | B8: 0.8 | C8: 1 | D8: 1.2 | E8: Medium reliability
A9: Wet-hire volume multiplier | B9: 0 | C9: 1 | D9: 2 | E9: Low reliability: 0 to double the plan
A10: Utilities multiplier | B10: 0.5 | C10: 1 | D10: 1.5 | E10: Low reliability
A11: Core staff cost multiplier | B11: 0.75 | C11: 1 | D11: 1.25 | E11: Low reliability
A12: Catering cost multiplier | B12: 0.8 | C12: 1 | D12: 1.2 | E12: Medium reliability
A13: Heritage maintenance multiplier | B13: 0.5 | C13: 1 | D13: 3 | E13: Low reliability; one-sided heritage risk (State-listed, fair condition)
A15: Result | B15: Case A (benchmark growth) | C15: Case B (stress growth)
A16: Year 5 surplus: 5th percentile | B16: -55928.102 | C16: -86733.884
A17: Year 5 surplus: median | B17: 113969.99 | C17: 85439.787
A18: Year 5 surplus: 95th percentile | B18: 289950.78 | C18: 263209.89
A19: P(Year 5 surplus < $0) | B19: 0.1386 | C19: 0.2111
A20: P(Year 5 surplus < 3% of average investment, $13.1k) | B20: 0.169 | C20: 0.2483
A21: P(Year 5 surplus < 3% of $1M, $30k) | B21: 0.212 | C21: 0.3023
A22: P(5-year average surplus < 3% of $1M) | B22: 0.8151 | C22: 0.8479
A23: Finance plan percentile within Year 5 distribution | B23: 0.8001 | C23: 0.863
A25: Rank correlation (Spearman) with Year 5 surplus | B25: Case A | C25: Case B
A26: Launch volume | B26: 0.69763002 | C26: 0.66333833
A27: Price | B27: 0.44136307 | C27: 0.41967417
A28: Core staff | B28: -0.26766263 | C28: -0.26859127
A29: Wet-hire volume | B29: 0.25328202 | C29: 0.25149455
A30: Contractor rates | B30: -0.24055105 | C30: -0.2297074
A31: Utilities | B31: -0.13234468 | C31: -0.13086943
A32: Annual growth | B32: 0.12696547 | C32: 0.29102365
A33: Catering | B33: -0.072949604 | C33: -0.071246859
A34: Heritage maintenance | B34: -0.070777139 | C34: -0.067799528

Sheet ModelRisk
A1: Model-risk stress: cost lines that look light in Finance's workbook
A2: Illustrative adjustments to Year 5 surplus. Blue cells are analyst assumptions anchored to the source in column D; change them to test other values. Not Finance numbers.
A4: Assumption | B4: Value | C4: Unit | D4: Basis
A5: Catering uplift | B5: 0.5 | C5: % of Finance catering cost | D5: (NSW Sport and Recreation, 2026) catered vs uncatered day price implies about $22.50 per student-day; compare with the catering line in (Drake, 2026a)
A6: Extra kitchen / cleaning staff | B6: 1 | C6: FTE | D6: (Drake, 2026a) Staffing tab lists a Site Manager and 3 General Supervisors; no cook, cleaner or night staff
A7: Cost per extra FTE | B7: 70611.818 | C7: $ per year | D7: (Drake, 2026a) Staffing tab: General Supervisor annual cost incl. on-costs
A8: Extra insurance | B8: 20000 | C8: $ per year | D8: Our assumption: (Drake, 2026a) costs $10,000 of public liability cover only
A9: Alternative day-program price | B9: 83 | C9: $ per student-day | D9: (NSW Sport and Recreation, 2026) catered day program price; cost-plus day price in (Drake, 2026a) is $98.60
A11: Finance plan Year 5 operating surplus (2.5 basis) | B11: =Scenarios!G88
A12: Finance Year 5 catering cost | B12: =Scenarios!G75
A13: Finance Year 5 day-program student-days | B13: =Scenarios!G65
A14: Finance day-program price | B14: =Inputs!$B$4
A15: Hurdle surplus: 3% of $1M | B15: =Inputs!$B$19*Inputs!$B$15
A17: Case | B17: Change to Year 5 surplus (simple formula) | C17: Year 5 surplus (simple formula) | D17: Above $30k hurdle? | E17: Python result incl. policy offset (authoritative)
A18: Finance plan (no change) | B18: =0 | C18: =$B$11+B18 | D18: =IF(C18>=$B$15,"Yes","No") | E18: 203657.1
A19: Catering uplift | B19: =-B5*B12 | C19: =$B$11+B19 | D19: =IF(C19>=$B$15,"Yes","No") | E19: 139162.17
A20: Extra kitchen / cleaning staff | B20: =-B6*B7 | C20: =$B$11+B20 | D20: =IF(C20>=$B$15,"Yes","No") | E20: 135841.51
A21: Extra insurance | B21: =-B8 | C21: =$B$11+B21 | D21: =IF(C21>=$B$15,"Yes","No") | E21: 184449.1
A22: Day price at alternative | B22: =-(B14-B9)*B13 | C22: =$B$11+B22 | D22: =IF(C22>=$B$15,"Yes","No") | E22: 152618.71
A23: Mild: catering + one FTE + insurance | B23: =B19+B20+B21 | C23: =$B$11+B23 | D23: =IF(C23>=$B$15,"Yes","No") | E23: 51929.622
A24: Heavier: catering + two FTE + insurance + day price | B24: =B19+2*B20+B21+B22 | C24: =$B$11+B24 | D24: =IF(C24>=$B$15,"Yes","No") | E24: -70742.786
A26: Note: the heavier case uses 2 x the per-FTE cost in B7 regardless of B6, so B6 only drives the single-FTE row and the mild case.
A27: Column E is the exact Python result. It differs from the simple formula by a few thousand dollars because lower surplus also lowers the 50% conservation reinvestment and its depreciation (Section 2.5 layer).

Sheet Comparators
A1: Comparator charities: cost structure and growth
A2: Latest-year figures reclassified onto a common cost structure by (Quang, 2026), from the statements of (Stewart House, 2025), (Crusader Union, 2025) and (YMCA Camping Ltd, 2025). Ratios are formulas.
A4: Latest year, $ | B4: Stewart House (CY2024) | C4: Crusader Union (FY2024-25) | D4: YMCA Camping (FY2025) | E4: Source
A5: Total revenue | B5: 3316064 | C5: 19009565 | D5: 21166872 | E5: (Quang, 2026) Comparable Benchmark!B8:D8
A6: Employee expenses | B6: 3187539 | C6: 10169973 | D6: 10319033 | E6: (Quang, 2026) Comparable Benchmark!B9:D9
A7: Depreciation and amortization | B7: 194899 | C7: 1848860 | D7: 787682 | E7: (Quang, 2026) Comparable Benchmark!B10:D10
A8: Admin-like overhead | B8: 906189 | C8: 3786924 | D8: 2472638 | E8: (Quang, 2026) Comparable Benchmark!B11:D11
A9: Operations and program costs | B9: 633489 | C9: 2922135 | D9: 5984943 | E9: (Quang, 2026) Comparable Benchmark!B12:D12
A10: Other (gain or loss on disposals) | B10: 0 | C10: 0 | D10: -33360 | E10: (Quang, 2026) Comparable Benchmark!B13:D13
A11: Total expenses | B11: =SUM(B6:B10) | C11: =SUM(C6:C10) | D11: =SUM(D6:D10)
A12: Surplus or (deficit) | B12: =B5-B11 | C12: =C5-C11 | D12: =D5-D11
A14: Ratios (% of revenue) | B14: Stewart House | C14: Crusader Union | D14: YMCA Camping | E14: Finance plan, Year 5
A15: Total expense ratio | B15: =B11/B5 | C15: =C11/C5 | D15: =D11/D5 | E15: =Summary!D11 | F15: (Drake, 2026b), total cost including depreciation / revenue
A16: Employee cost ratio | B16: =B6/B5 | C16: =C6/C5 | D16: =D6/D5
A17: Surplus or (deficit) margin | B17: =B12/B5 | C17: =C12/C5 | D17: =D12/D5
A19: Crusader Union: capital-campaign adjustment
A20: Revenue excluding capital-campaign donations, FY2024-25 | C20: 18249398 | E20: (Crusader Union, 2025) Annual Report FY2024-25
A21: Revenue excluding capital-campaign donations, FY2023-24 | C21: 16813900 | E21: (Crusader Union, 2025) Annual Report FY2024-25, prior-year column
A22: Capital-campaign donations, FY2024-25 | C22: =C5-C20
A23: Capital-campaign donations, FY2023-24 | C23: =16822335-C21 | E23: FY2023-24 reported revenue $16,822,335 (Quang, 2026) Growth Trend!B29
A24: Expense ratio excluding campaign donations | C24: =C11/C20
A26: Stewart House: donations share of income, CY2024
A27: Donations: schools + salary contributions + corporate and other | B27: =214419+1197181+1214314 | E27: (Stewart House, 2025) statement of surplus or deficit, 2024 column
A28: Share of total revenue | B28: =B27/B5
A30: Year-on-year revenue growth | B30: Prior year, $ | C30: Latest year, $ | D30: Growth | E30: Source
A31: Stewart House CY2023 to CY2024 | B31: 3162237 | C31: 3316064 | D31: =C31/B31-1 | E31: (Stewart House, 2025)
A32: Crusader Union FY2023-24 to FY2024-25 (excl. capital campaign) | B32: 16813900 | C32: 18249398 | D32: =C32/B32-1 | E32: (Crusader Union, 2025)
A33: YMCA Camping FY2023 to FY2024 | B33: 18921663 | C33: 19825707 | D33: =C33/B33-1 | E33: (YMCA Camping Ltd, 2024)
A34: YMCA Camping FY2024 to FY2025 | B34: 19825707 | C34: 21166872 | D34: =C34/B34-1 | E34: (YMCA Camping Ltd, 2025)
A35: Minimum / mean / maximum | B35: =MIN(D31:D34) | C35: =AVERAGE(D31:D34) | D35: =MAX(D31:D34) | E35: Feeds the Low, Base and High growth rates on the Inputs sheet

Sheet Recommendations
A1: Recommendations: cost of heritage and access commitments (static output of tradeoff2.py)
A2: Deterministic columns: Finance plan volumes, Year 5. Simulation columns: 10,000 runs, seed 42, same random draws in every row. Discount = 25% on the share of school student-days offered to local or under-resourced schools (our assumption); conservation share = share of surplus reinvested in conservation (Finance: 50%, Drake, 2026b).
A4: Package | B4: Access share (25% discount) | C4: Maintenance multiple | D4: Conservation share | E4: Discount timing | F4: Y5 surplus (Finance plan) | G4: ARR (Finance plan) | H4: Lowest cash (Finance plan) | I4: Five-year conservation spend | J4: Simulated median Y5 surplus | K4: Share of runs below $13,100 | L4: Share of runs with negative cash
A5: Finance plan | B5: 0 | C5: 1 | D5: 0.5 | E5: n/a | F5: 203657.1 | G5: 0.46647133 | H5: 189424.15 | I5: 431041.49 | J5: 113969.99 | K5: 0.169 | L5: 0.2816
A6: 75% conservation share | B6: 0 | C6: 1 | D6: 0.75 | E6: n/a | F6: 200228.05 | G6: 0.41761687 | H6: 189424.15 | I6: 516767.72 | J6: 112098.13 | K6: 0.1693 | L6: 0.2816
A7: Maintenance doubled | B7: 0 | C7: 2 | D7: 0.5 | E7: n/a | F7: 184449.1 | G7: 0.43227811 | H7: 129424.15 | I7: 511241.49 | J7: 85796.814 | K7: 0.2498 | L7: 0.4524
A8: Maintenance tripled | B8: 0 | C8: 3 | D8: 0.5 | E8: n/a | J8: 57379.181 | K8: 0.3461 | L8: 0.6197
A9: 10% access from the start (50% share) | B9: 0.1 | C9: 1 | D9: 0.5 | E9: From the start | F9: 170088.94 | G9: 0.40486913 | H9: 134629.85 | I9: 398076.78
A10: 10% access from the start (75% share) | B10: 0.1 | C10: 1 | D10: 0.75 | E10: From the start | J10: 82807.229 | K10: 0.2459 | L10: 0.3786
A11: 20% access from the start (75% share) | B11: 0.2 | C11: 1 | D11: 0.75 | E11: From the start | F11: 134391.32 | G11: 0.3123604 | H11: 79835.552 | I11: 418348.72 | J11: 53261.709 | K11: 0.3475 | L11: 0.4846
A12: 10% access, conditional (75% share): recommended | B12: 0.1 | C12: 1 | D12: 0.75 | E12: After Year 2 bookings reach 9,700 | F12: 167309.69 | G12: 0.36783553 | H12: 134629.85 | I12: 467558.22 | J12: 98567.877 | K12: 0.1838 | L12: 0.3069
A13: 20% access, conditional (75% share) | B13: 0.2 | C13: 1 | D13: 0.75 | E13: After Year 2 bookings reach 9,700 | J13: 84650.189 | K13: 0.2108 | L13: 0.3506
A14: 30% access, conditional (75% share) | B14: 0.3 | C14: 1 | D14: 0.75 | E14: After Year 2 bookings reach 9,700 | J14: 69780.959 | K14: 0.2512 | L14: 0.4065
A15: Recommended package with maintenance doubled | B15: 0.1 | C15: 2 | D15: 0.75 | E15: After Year 2 bookings reach 9,700 | J15: 70610.43 | K15: 0.2771 | L15: 0.5002
A17: Share of simulated futures in which Year 2 bookings reach the 9,700 trigger (launch multiplier of 1.00 or more) | F17: 0.4475
A18: Finance plan school student-days in Year 5 (for the 10% share) | F18: =Scenarios!G63
A19: Student-days at a 10% share | F19: =0.1*F18
A21: Blank cells were not run. The model applies the discount from Year 2, which overstates its cost slightly. We have no data on how demand responds to price, so higher prices are not tested. Contingency of $92,575 is held until Year 2 volume reaches break-even (Drake, 2026b, Inputs!B9; Drake, 2026a, Break-Even!D44).

Sheet Chapter_Check
A1: Chapter check: every figure in the chapter against this workbook
A2: Chapter value = the number as written in the chapter (rounded). Workbook value = live link to the cell that produces it (blue = static value from a Finance workbook). Check = OK if the two agree within the tolerance.
A4: Chapter part | B4: Statement in the chapter | C4: Chapter value | D4: Workbook value | E4: Tolerance | F4: Check | G4: Where it comes from
A5: Comparators | B5: Stewart House expense ratio | C5: 1.48 | D5: =Comparators!B15 | E5: 0.005 | F5: =IF(ABS(D5-C5)<=E5,"OK","CHECK") | G5: (Quang, 2026); (Stewart House, 2025)
A6: Comparators | B6: Crusader Union expense ratio | C6: 0.99 | D6: =Comparators!C15 | E6: 0.005 | F6: =IF(ABS(D6-C6)<=E6,"OK","CHECK") | G6: (Quang, 2026); (Crusader Union, 2025)
A7: Comparators | B7: YMCA Camping expense ratio | C7: 0.92 | D7: =Comparators!D15 | E7: 0.005 | F7: =IF(ABS(D7-C7)<=E7,"OK","CHECK") | G7: (Quang, 2026); (YMCA Camping Ltd, 2025)
A8: Comparators | B8: Employee costs: YMCA Camping | C8: 0.49 | D8: =Comparators!D16 | E8: 0.005 | F8: =IF(ABS(D8-C8)<=E8,"OK","CHECK") | G8: Comparators sheet
A9: Comparators | B9: Employee costs: Crusader Union | C9: 0.53 | D9: =Comparators!C16 | E9: 0.005 | F9: =IF(ABS(D9-C9)<=E9,"OK","CHECK") | G9: Comparators sheet
A10: Comparators | B10: Employee costs: Stewart House | C10: 0.96 | D10: =Comparators!B16 | E10: 0.005 | F10: =IF(ABS(D10-C10)<=E10,"OK","CHECK") | G10: Comparators sheet
A11: Comparators | B11: YMCA Camping surplus margin | C11: 0.077 | D11: =Comparators!D17 | E11: 0.0005 | F11: =IF(ABS(D11-C11)<=E11,"OK","CHECK") | G11: Comparators sheet
A12: Comparators | B12: Growth range: lowest | C12: 0.048 | D12: =Inputs!D36 | E12: 0.0005 | F12: =IF(ABS(D12-C12)<=E12,"OK","CHECK") | G12: Inputs sheet
A13: Comparators | B13: Growth range: mean | C13: 0.062 | D13: =Inputs!D37 | E13: 0.0005 | F13: =IF(ABS(D13-C13)<=E13,"OK","CHECK") | G13: Inputs sheet
A14: Comparators | B14: Growth range: highest | C14: 0.085 | D14: =Inputs!D38 | E14: 0.0005 | F14: =IF(ABS(D14-C14)<=E14,"OK","CHECK") | G14: Inputs sheet
A15: Comparators | B15: Crusader Union capital-campaign donations, latest year | C15: 760000 | D15: =Comparators!C22 | E15: 500 | F15: =IF(ABS(D15-C15)<=E15,"OK","CHECK") | G15: (Crusader Union, 2025)
A16: Comparators | B16: Crusader Union capital-campaign donations, year before | C16: 8000 | D16: =Comparators!C23 | E16: 500 | F16: =IF(ABS(D16-C16)<=E16,"OK","CHECK") | G16: (Crusader Union, 2025)
A17: Comparators | B17: Crusader Union expense ratio without donations | C17: 1.03 | D17: =Comparators!C24 | E17: 0.005 | F17: =IF(ABS(D17-C17)<=E17,"OK","CHECK") | G17: Comparators sheet
A18: Comparators | B18: Stewart House deficit as share of revenue | C18: -0.48 | D18: =Comparators!B17 | E18: 0.005 | F18: =IF(ABS(D18-C18)<=E18,"OK","CHECK") | G18: Comparators sheet
A19: Comparators | B19: Stewart House donations share of income | C19: 0.79 | D19: =Comparators!B28 | E19: 0.005 | F19: =IF(ABS(D19-C19)<=E19,"OK","CHECK") | G19: (Stewart House, 2025)
A20: Demand | B20: Finance Year 2 launch volume (student-days) | C20: 9720 | D20: =Inputs!D56 | E20: 0.5 | F20: =IF(ABS(D20-C20)<=E20,"OK","CHECK") | G20: (Drake, 2026a) Volumes
A21: Demand | B21: Low launch size as share of Base (50 of 72) | C21: 0.69 | D21: =Inputs!$C$42 | E21: 0.005 | F21: =IF(ABS(D21-C21)<=E21,"OK","CHECK") | G21: Inputs sheet
A22: Demand | B22: High launch size as share of Base (90 of 72) | C22: 1.25 | D22: =Inputs!$C$44 | E22: 0.005 | F22: =IF(ABS(D22-C22)<=E22,"OK","CHECK") | G22: Inputs sheet
A23: Demand | B23: Year 5 student-days, Low | C23: 7764 | D23: =Summary!B7 | E23: 0.5 | F23: =IF(ABS(D23-C23)<=E23,"OK","CHECK") | G23: Summary
A24: Demand | B24: Year 5 student-days, Base | C24: 11654 | D24: =Summary!C7 | E24: 0.5 | F24: =IF(ABS(D24-C24)<=E24,"OK","CHECK") | G24: Summary
A25: Demand | B25: Year 5 student-days, High | C25: 15535 | D25: =Summary!E7 | E25: 0.5 | F25: =IF(ABS(D25-C25)<=E25,"OK","CHECK") | G25: Summary
A26: Demand | B26: Finance Year 5 student-days | C26: 12897 | D26: =Summary!D7 | E26: 0.5 | F26: =IF(ABS(D26-C26)<=E26,"OK","CHECK") | G26: Summary
A27: Demand | B27: Finance Year 5 break-even (student-days) | C27: 10486 | D27: 10486 | E27: 0.5 | F27: =IF(ABS(D27-C27)<=E27,"OK","CHECK") | G27: (Drake, 2026a) Break-Even!G44
A28: Demand | B28: Base Year 2 volume above Finance Year 2 break-even (9,687) | C28: 0.003 | D28: =Scenarios!D34/9687-1 | E28: 0.0005 | F28: =IF(ABS(D28-C28)<=E28,"OK","CHECK") | G28: (Drake, 2026a) Break-Even!D44
A29: Demand | B29: Occupancy, lowest (Low, Year 2) | C29: 0.1 | D29: =Scenarios!D6 | E29: 0.005 | F29: =IF(ABS(D29-C29)<=E29,"OK","CHECK") | G29: Scenarios
A30: Demand | B30: Occupancy, highest (High, Year 5) | C30: 0.23 | D30: =Scenarios!G93 | E30: 0.005 | F30: =IF(ABS(D30-C30)<=E30,"OK","CHECK") | G30: Scenarios
A31: Demand | B31: Capacity (student-days) | C31: 67500 | D31: =Inputs!$B$21 | E31: 0.5 | F31: =IF(ABS(D31-C31)<=E31,"OK","CHECK") | G31: (Drake, 2026a) Assumptions
A32: Return | B32: Year 5 surplus, Low | C32: -92000 | D32: =Summary!B10 | E32: 500 | F32: =IF(ABS(D32-C32)<=E32,"OK","CHECK") | G32: Summary
A33: Return | B33: Year 5 surplus, Base | C33: 133000 | D33: =Summary!C10 | E33: 500 | F33: =IF(ABS(D33-C33)<=E33,"OK","CHECK") | G33: Summary
A34: Return | B34: Year 5 surplus, Finance | C34: 204000 | D34: =Summary!D10 | E34: 500 | F34: =IF(ABS(D34-C34)<=E34,"OK","CHECK") | G34: Summary; (Drake, 2026b) Calculations!H84
A35: Return | B35: Year 5 surplus, High | C35: 350000 | D35: =Summary!E10 | E35: 500 | F35: =IF(ABS(D35-C35)<=E35,"OK","CHECK") | G35: Summary
A36: Return | B36: Average investment | C36: 437000 | D36: =Summary!D12 | E36: 500 | F36: =IF(ABS(D36-C36)<=E36,"OK","CHECK") | G36: (Drake, 2026b) Calculations!H83
A37: Return | B37: Hurdle surplus (3% of average investment) | C37: 13100 | D37: =Summary!D13 | E37: 50 | F37: =IF(ABS(D37-C37)<=E37,"OK","CHECK") | G37: Summary
A38: Return | B38: Finance ARR, Year 5 | C38: 0.47 | D38: =Summary!D15 | E38: 0.005 | F38: =IF(ABS(D38-C38)<=E38,"OK","CHECK") | G38: (Drake, 2026b) Calculations!H85
A39: Sensitivity | B39: Volume -20%: Year 5 surplus | C39: 57000 | D39: =Sensitivity!D5 | E39: 500 | F39: =IF(ABS(D39-C39)<=E39,"OK","CHECK") | G39: Sensitivity
A40: Sensitivity | B40: Volume +20%: Year 5 surplus | C40: 348000 | D40: =Sensitivity!E5 | E40: 500 | F40: =IF(ABS(D40-C40)<=E40,"OK","CHECK") | G40: Sensitivity
A41: Sensitivity | B41: Price -10%: Year 5 surplus | C41: 69000 | D41: =Sensitivity!D6 | E41: 500 | F41: =IF(ABS(D41-C41)<=E41,"OK","CHECK") | G41: Sensitivity
...

Sheet References
A1: References
A3: Crusader Union (2025) Annual report 2024–25.
A4: Drake, J. (2026a) Hillview cost structure and break-even (FINAL) [Excel workbook]. MQBS3010 Group 1I, Macquarie University. Unpublished.
A5: Drake, J. (2026b) Hillview performance and returns (FINAL) [Excel workbook]. MQBS3010 Group 1I, Macquarie University. Unpublished.
A6: Drake, J. (2026c) Hillview capital allocation (FINAL) [Excel workbook]. MQBS3010 Group 1I, Macquarie University. Unpublished.
A7: Flyvbjerg, B. (2009) 'Survival of the unfittest: why the worst infrastructure gets built and what we can do about it', Oxford Review of Economic Policy, 25(3), pp. 344–367.
A8: NSW Sport and Recreation (2026) Camp price list: school programs. Available at: https://sport.nsw.gov.au/sites/default/files/2025-03/Website_Camp_Pricelist_Centres_2026.pdf
A9: Quang, N. (2026) Hillview comparable charity benchmarking [Excel workbook]. MQBS3010 Group 1I, Macquarie University. Unpublished.
A10: Quang, N. (2026) Hillview Harmony: Business Analytics scenario model [Excel workbook]. MQBS3010 Group 1I, Macquarie University. Unpublished.
A11: Quang, N. (2026) Hillview Harmony: Business Analytics model [Python code]. MQBS3010 Group 1I, Macquarie University. Unpublished.
A12: Saltelli, A., Ratto, M., Andres, T., Campolongo, F., Cariboni, J., Gatelli, D., Saisana, M. and Tarantola, S. (2008) Global sensitivity analysis: the primer. Chichester: Wiley.
A13: Savage, S.L. (2012) The flaw of averages: why we underestimate risk in the face of uncertainty. Hoboken: Wiley.
... A19: Titles of books, reports and journals are italic in the chapter; plain text is used here. The three Drake entries are lettered by workbook so that (Drake, 2026a) and (Drake, 2026b) match the chapter; (Drake, 2026c) is cited only in this workbook.
